Internal Server Error: /support
Traceback (most recent call last):
  File "/usr/local/lib/python3.8/site-packages/django/core/handlers/exception.py", line 55, in inner
    response = get_response(request)
  File "/kreeckacademy/support/middleware.py", line 12, in __call__
    self.log_error(request, response.status_code)
  File "/kreeckacademy/support/middleware.py", line 17, in log_error
    if not SupportTicket.objects.filter(error_code=error_code).exists():
  File "/usr/local/lib/python3.8/site-packages/django/db/models/manager.py", line 87, in manager_method
    return getattr(self.get_queryset(), name)(*args, **kwargs)
  File "/usr/local/lib/python3.8/site-packages/django/db/models/query.py", line 1436, in filter
    return self._filter_or_exclude(False, args, kwargs)
  File "/usr/local/lib/python3.8/site-packages/django/db/models/query.py", line 1454, in _filter_or_exclude
    clone._filter_or_exclude_inplace(negate, args, kwargs)
  File "/usr/local/lib/python3.8/site-packages/django/db/models/query.py", line 1461, in _filter_or_exclude_inplace
    self._query.add_q(Q(*args, **kwargs))
  File "/usr/local/lib/python3.8/site-packages/django/db/models/sql/query.py", line 1546, in add_q
    clause, _ = self._add_q(q_object, self.used_aliases)
  File "/usr/local/lib/python3.8/site-packages/django/db/models/sql/query.py", line 1577, in _add_q
    child_clause, needed_inner = self.build_filter(
  File "/usr/local/lib/python3.8/site-packages/django/db/models/sql/query.py", line 1427, in build_filter
    lookups, parts, reffed_expression = self.solve_lookup_type(arg, summarize)
  File "/usr/local/lib/python3.8/site-packages/django/db/models/sql/query.py", line 1237, in solve_lookup_type
    _, field, _, lookup_parts = self.names_to_path(lookup_splitted, self.get_meta())
  File "/usr/local/lib/python3.8/site-packages/django/db/models/sql/query.py", line 1725, in names_to_path
    raise FieldError(
django.core.exceptions.FieldError: Cannot resolve keyword 'error_code' into field. Choices are: assigned_to, assigned_to_id, id, resolution_notes, resolved_at, ticket, ticket_id
"GET /support HTTP/1.1" 500 121132
Internal Server Error: /favicon.ico
Traceback (most recent call last):
  File "/usr/local/lib/python3.8/site-packages/django/core/handlers/exception.py", line 55, in inner
    response = get_response(request)
  File "/kreeckacademy/support/middleware.py", line 12, in __call__
    self.log_error(request, response.status_code)
  File "/kreeckacademy/support/middleware.py", line 17, in log_error
    if not SupportTicket.objects.filter(error_code=error_code).exists():
  File "/usr/local/lib/python3.8/site-packages/django/db/models/manager.py", line 87, in manager_method
    return getattr(self.get_queryset(), name)(*args, **kwargs)
  File "/usr/local/lib/python3.8/site-packages/django/db/models/query.py", line 1436, in filter
    return self._filter_or_exclude(False, args, kwargs)
  File "/usr/local/lib/python3.8/site-packages/django/db/models/query.py", line 1454, in _filter_or_exclude
    clone._filter_or_exclude_inplace(negate, args, kwargs)
  File "/usr/local/lib/python3.8/site-packages/django/db/models/query.py", line 1461, in _filter_or_exclude_inplace
    self._query.add_q(Q(*args, **kwargs))
  File "/usr/local/lib/python3.8/site-packages/django/db/models/sql/query.py", line 1546, in add_q
    clause, _ = self._add_q(q_object, self.used_aliases)
  File "/usr/local/lib/python3.8/site-packages/django/db/models/sql/query.py", line 1577, in _add_q
    child_clause, needed_inner = self.build_filter(
  File "/usr/local/lib/python3.8/site-packages/django/db/models/sql/query.py", line 1427, in build_filter
    lookups, parts, reffed_expression = self.solve_lookup_type(arg, summarize)
  File "/usr/local/lib/python3.8/site-packages/django/db/models/sql/query.py", line 1237, in solve_lookup_type
    _, field, _, lookup_parts = self.names_to_path(lookup_splitted, self.get_meta())
  File "/usr/local/lib/python3.8/site-packages/django/db/models/sql/query.py", line 1725, in names_to_path
    raise FieldError(
django.core.exceptions.FieldError: Cannot resolve keyword 'error_code' into field. Choices are: assigned_to, assigned_to_id, id, resolution_notes, resolved_at, ticket, ticket_id
"GET /favicon.ico HTTP/1.1" 500 120987
Internal Server Error: /support
Traceback (most recent call last):
  File "/usr/local/lib/python3.8/site-packages/django/core/handlers/exception.py", line 55, in inner
    response = get_response(request)
  File "/kreeckacademy/support/middleware.py", line 12, in __call__
    self.log_error(request, response.status_code)
  File "/kreeckacademy/support/middleware.py", line 17, in log_error
    if not SupportTicket.objects.filter(error_code=error_code).exists():
  File "/usr/local/lib/python3.8/site-packages/django/db/models/manager.py", line 87, in manager_method
    return getattr(self.get_queryset(), name)(*args, **kwargs)
  File "/usr/local/lib/python3.8/site-packages/django/db/models/query.py", line 1436, in filter
    return self._filter_or_exclude(False, args, kwargs)
  File "/usr/local/lib/python3.8/site-packages/django/db/models/query.py", line 1454, in _filter_or_exclude
    clone._filter_or_exclude_inplace(negate, args, kwargs)
  File "/usr/local/lib/python3.8/site-packages/django/db/models/query.py", line 1461, in _filter_or_exclude_inplace
    self._query.add_q(Q(*args, **kwargs))
  File "/usr/local/lib/python3.8/site-packages/django/db/models/sql/query.py", line 1546, in add_q
    clause, _ = self._add_q(q_object, self.used_aliases)
  File "/usr/local/lib/python3.8/site-packages/django/db/models/sql/query.py", line 1577, in _add_q
    child_clause, needed_inner = self.build_filter(
  File "/usr/local/lib/python3.8/site-packages/django/db/models/sql/query.py", line 1427, in build_filter
    lookups, parts, reffed_expression = self.solve_lookup_type(arg, summarize)
  File "/usr/local/lib/python3.8/site-packages/django/db/models/sql/query.py", line 1237, in solve_lookup_type
    _, field, _, lookup_parts = self.names_to_path(lookup_splitted, self.get_meta())
  File "/usr/local/lib/python3.8/site-packages/django/db/models/sql/query.py", line 1725, in names_to_path
    raise FieldError(
django.core.exceptions.FieldError: Cannot resolve keyword 'error_code' into field. Choices are: assigned_to, assigned_to_id, id, resolution_notes, resolved_at, ticket, ticket_id
"GET /support HTTP/1.1" 500 121269
Internal Server Error: /favicon.ico
Traceback (most recent call last):
  File "/usr/local/lib/python3.8/site-packages/django/core/handlers/exception.py", line 55, in inner
    response = get_response(request)
  File "/kreeckacademy/support/middleware.py", line 12, in __call__
    self.log_error(request, response.status_code)
  File "/kreeckacademy/support/middleware.py", line 17, in log_error
    if not SupportTicket.objects.filter(error_code=error_code).exists():
  File "/usr/local/lib/python3.8/site-packages/django/db/models/manager.py", line 87, in manager_method
    return getattr(self.get_queryset(), name)(*args, **kwargs)
  File "/usr/local/lib/python3.8/site-packages/django/db/models/query.py", line 1436, in filter
    return self._filter_or_exclude(False, args, kwargs)
  File "/usr/local/lib/python3.8/site-packages/django/db/models/query.py", line 1454, in _filter_or_exclude
    clone._filter_or_exclude_inplace(negate, args, kwargs)
  File "/usr/local/lib/python3.8/site-packages/django/db/models/query.py", line 1461, in _filter_or_exclude_inplace
    self._query.add_q(Q(*args, **kwargs))
  File "/usr/local/lib/python3.8/site-packages/django/db/models/sql/query.py", line 1546, in add_q
    clause, _ = self._add_q(q_object, self.used_aliases)
  File "/usr/local/lib/python3.8/site-packages/django/db/models/sql/query.py", line 1577, in _add_q
    child_clause, needed_inner = self.build_filter(
  File "/usr/local/lib/python3.8/site-packages/django/db/models/sql/query.py", line 1427, in build_filter
    lookups, parts, reffed_expression = self.solve_lookup_type(arg, summarize)
  File "/usr/local/lib/python3.8/site-packages/django/db/models/sql/query.py", line 1237, in solve_lookup_type
    _, field, _, lookup_parts = self.names_to_path(lookup_splitted, self.get_meta())
  File "/usr/local/lib/python3.8/site-packages/django/db/models/sql/query.py", line 1725, in names_to_path
    raise FieldError(
django.core.exceptions.FieldError: Cannot resolve keyword 'error_code' into field. Choices are: assigned_to, assigned_to_id, id, resolution_notes, resolved_at, ticket, ticket_id
"GET /favicon.ico HTTP/1.1" 500 120987
Internal Server Error: /support/support/dashboard
Traceback (most recent call last):
  File "/usr/local/lib/python3.8/site-packages/django/core/handlers/exception.py", line 55, in inner
    response = get_response(request)
  File "/usr/local/lib/python3.8/site-packages/django/core/handlers/base.py", line 197, in _get_response
    response = wrapped_callback(request, *callback_args, **callback_kwargs)
  File "/usr/local/lib/python3.8/site-packages/django/contrib/auth/decorators.py", line 23, in _wrapper_view
    return view_func(request, *args, **kwargs)
  File "/usr/local/lib/python3.8/site-packages/django/contrib/auth/decorators.py", line 23, in _wrapper_view
    return view_func(request, *args, **kwargs)
  File "/kreeckacademy/support/views.py", line 113, in support_dashboard
    tickets = SupportTicket.objects.all().order_by('-created_at')
  File "/usr/local/lib/python3.8/site-packages/django/db/models/query.py", line 1659, in order_by
    obj.query.add_ordering(*field_names)
  File "/usr/local/lib/python3.8/site-packages/django/db/models/sql/query.py", line 2222, in add_ordering
    self.names_to_path(item.split(LOOKUP_SEP), self.model._meta)
  File "/usr/local/lib/python3.8/site-packages/django/db/models/sql/query.py", line 1725, in names_to_path
    raise FieldError(
django.core.exceptions.FieldError: Cannot resolve keyword 'created_at' into field. Choices are: assigned_to, assigned_to_id, id, resolution_notes, resolved_at, ticket, ticket_id
"GET /support/support/dashboard HTTP/1.1" 500 103550
Internal Server Error: /support/dashboard
Traceback (most recent call last):
  File "/usr/local/lib/python3.8/site-packages/django/core/handlers/exception.py", line 55, in inner
    response = get_response(request)
  File "/usr/local/lib/python3.8/site-packages/django/core/handlers/base.py", line 197, in _get_response
    response = wrapped_callback(request, *callback_args, **callback_kwargs)
  File "/usr/local/lib/python3.8/site-packages/django/contrib/auth/decorators.py", line 23, in _wrapper_view
    return view_func(request, *args, **kwargs)
  File "/usr/local/lib/python3.8/site-packages/django/contrib/auth/decorators.py", line 23, in _wrapper_view
    return view_func(request, *args, **kwargs)
  File "/kreeckacademy/support/views.py", line 113, in support_dashboard
    tickets = SupportTicket.objects.all().order_by('-created_at')
  File "/usr/local/lib/python3.8/site-packages/django/db/models/query.py", line 1659, in order_by
    obj.query.add_ordering(*field_names)
  File "/usr/local/lib/python3.8/site-packages/django/db/models/sql/query.py", line 2222, in add_ordering
    self.names_to_path(item.split(LOOKUP_SEP), self.model._meta)
  File "/usr/local/lib/python3.8/site-packages/django/db/models/sql/query.py", line 1725, in names_to_path
    raise FieldError(
django.core.exceptions.FieldError: Cannot resolve keyword 'created_at' into field. Choices are: assigned_to, assigned_to_id, id, resolution_notes, resolved_at, ticket, ticket_id
"GET /support/dashboard HTTP/1.1" 500 103447
Internal Server Error: /support/dashboard/
Traceback (most recent call last):
  File "/usr/local/lib/python3.8/site-packages/django/core/handlers/exception.py", line 55, in inner
    response = get_response(request)
  File "/usr/local/lib/python3.8/site-packages/django/core/handlers/base.py", line 197, in _get_response
    response = wrapped_callback(request, *callback_args, **callback_kwargs)
  File "/usr/local/lib/python3.8/site-packages/django/contrib/auth/decorators.py", line 23, in _wrapper_view
    return view_func(request, *args, **kwargs)
  File "/usr/local/lib/python3.8/site-packages/django/contrib/auth/decorators.py", line 23, in _wrapper_view
    return view_func(request, *args, **kwargs)
  File "/kreeckacademy/support/views.py", line 113, in support_dashboard
    tickets = SupportTicket.objects.all().order_by('-created_at')
  File "/usr/local/lib/python3.8/site-packages/django/db/models/query.py", line 1659, in order_by
    obj.query.add_ordering(*field_names)
  File "/usr/local/lib/python3.8/site-packages/django/db/models/sql/query.py", line 2222, in add_ordering
    self.names_to_path(item.split(LOOKUP_SEP), self.model._meta)
  File "/usr/local/lib/python3.8/site-packages/django/db/models/sql/query.py", line 1725, in names_to_path
    raise FieldError(
django.core.exceptions.FieldError: Cannot resolve keyword 'created_at' into field. Choices are: assigned_to, assigned_to_id, id, resolution_notes, resolved_at, ticket, ticket_id
"GET /support/dashboard/ HTTP/1.1" 500 103596
Internal Server Error: /support/dashboard/
Traceback (most recent call last):
  File "/usr/local/lib/python3.8/site-packages/django/core/handlers/exception.py", line 55, in inner
    response = get_response(request)
  File "/usr/local/lib/python3.8/site-packages/django/core/handlers/base.py", line 197, in _get_response
    response = wrapped_callback(request, *callback_args, **callback_kwargs)
  File "/usr/local/lib/python3.8/site-packages/django/contrib/auth/decorators.py", line 23, in _wrapper_view
    return view_func(request, *args, **kwargs)
  File "/usr/local/lib/python3.8/site-packages/django/contrib/auth/decorators.py", line 23, in _wrapper_view
    return view_func(request, *args, **kwargs)
  File "/kreeckacademy/support/views.py", line 114, in support_dashboard
    return render(request, 'support/dashboard.html', {'tickets': tickets})
  File "/usr/local/lib/python3.8/site-packages/django/shortcuts.py", line 24, in render
    content = loader.render_to_string(template_name, context, request, using=using)
  File "/usr/local/lib/python3.8/site-packages/django/template/loader.py", line 61, in render_to_string
    template = get_template(template_name, using=using)
  File "/usr/local/lib/python3.8/site-packages/django/template/loader.py", line 15, in get_template
    return engine.get_template(template_name)
  File "/usr/local/lib/python3.8/site-packages/django/template/backends/django.py", line 33, in get_template
    return Template(self.engine.get_template(template_name), self)
  File "/usr/local/lib/python3.8/site-packages/django/template/engine.py", line 175, in get_template
    template, origin = self.find_template(template_name)
  File "/usr/local/lib/python3.8/site-packages/django/template/engine.py", line 157, in find_template
    template = loader.get_template(name, skip=skip)
  File "/usr/local/lib/python3.8/site-packages/django/template/loaders/cached.py", line 57, in get_template
    template = super().get_template(template_name, skip)
  File "/usr/local/lib/python3.8/site-packages/django/template/loaders/base.py", line 28, in get_template
    return Template(
  File "/usr/local/lib/python3.8/site-packages/django/template/base.py", line 154, in __init__
    self.nodelist = self.compile_nodelist()
  File "/usr/local/lib/python3.8/site-packages/django/template/base.py", line 200, in compile_nodelist
    return parser.parse()
  File "/usr/local/lib/python3.8/site-packages/django/template/base.py", line 513, in parse
    raise self.error(token, e)
  File "/usr/local/lib/python3.8/site-packages/django/template/base.py", line 511, in parse
    compiled_result = compile_func(self, token)
  File "/usr/local/lib/python3.8/site-packages/django/template/defaulttags.py", line 853, in do_for
    nodelist_loop = parser.parse(
  File "/usr/local/lib/python3.8/site-packages/django/template/base.py", line 484, in parse
    raise self.error(token, e)
  File "/usr/local/lib/python3.8/site-packages/django/template/base.py", line 482, in parse
    filter_expression = self.compile_filter(token.contents)
  File "/usr/local/lib/python3.8/site-packages/django/template/base.py", line 600, in compile_filter
    return FilterExpression(token, self)
  File "/usr/local/lib/python3.8/site-packages/django/template/base.py", line 703, in __init__
    raise TemplateSyntaxError(
django.template.exceptions.TemplateSyntaxError: Could not parse the remainder: ' if ticket.assigned_to else 'Unassigned'' from 'ticket.assigned_to.username if ticket.assigned_to else 'Unassigned''
"GET /support/dashboard/ HTTP/1.1" 500 185790
Internal Server Error: /support/test-error/
Traceback (most recent call last):
  File "/usr/local/lib/python3.8/site-packages/django/core/handlers/base.py", line 197, in _get_response
    response = wrapped_callback(request, *callback_args, **callback_kwargs)
  File "/kreeckacademy/support/views.py", line 134, in test_error
    raise ValueError("This is a test error.")
ValueError: This is a test error.

During handling of the above exception, another exception occurred:

Traceback (most recent call last):
  File "/usr/local/lib/python3.8/site-packages/django/core/handlers/exception.py", line 55, in inner
    response = get_response(request)
  File "/usr/local/lib/python3.8/site-packages/django/core/handlers/base.py", line 199, in _get_response
    response = self.process_exception_by_middleware(e, request)
  File "/usr/local/lib/python3.8/site-packages/django/core/handlers/base.py", line 362, in process_exception_by_middleware
    response = middleware_method(request, exception)
  File "/kreeckacademy/support/middleware.py", line 32, in process_exception
    return render(request, 'common/500.html', status=500)
  File "/usr/local/lib/python3.8/site-packages/django/shortcuts.py", line 24, in render
    content = loader.render_to_string(template_name, context, request, using=using)
  File "/usr/local/lib/python3.8/site-packages/django/template/loader.py", line 61, in render_to_string
    template = get_template(template_name, using=using)
  File "/usr/local/lib/python3.8/site-packages/django/template/loader.py", line 19, in get_template
    raise TemplateDoesNotExist(template_name, chain=chain)
django.template.exceptions.TemplateDoesNotExist: /500.html
"GET /support/test-error/ HTTP/1.1" 500 103536
Internal Server Error: /support/test-error/
"GET /support/test-error/ HTTP/1.1" 500 14694
Internal Server Error: /support/test-error/
"GET /support/test-error/ HTTP/1.1" 500 14692
Internal Server Error: /support/test-error/
"GET /support/test-error/ HTTP/1.1" 500 14692
Internal Server Error: /support/test-error/
"GET /support/test-error/ HTTP/1.1" 500 14692
Internal Server Error: /support/test-error/
"GET /support/test-error/ HTTP/1.1" 500 14694
Internal Server Error: /support/test-error/
"GET /support/test-error/ HTTP/1.1" 500 14694
Internal Server Error: /support/test-error/
"GET /support/test-error/ HTTP/1.1" 500 14694
Internal Server Error: /support/trigger-test-error/
"GET /support/trigger-test-error/ HTTP/1.1" 500 14709
Internal Server Error: /support/trigger-test-error/
"GET /support/trigger-test-error/ HTTP/1.1" 500 14708
Internal Server Error: /support/support/4/
"GET /support/support/4/ HTTP/1.1" 500 14703
Internal Server Error: /support/support/4/
"GET /support/support/4/ HTTP/1.1" 500 14702
Internal Server Error: /support/support/4/
"GET /support/support/4/ HTTP/1.1" 500 14702
Internal Server Error: /support/support/4/
"GET /support/support/4/ HTTP/1.1" 500 14703
Internal Server Error: /support/4/
"GET /support/4/ HTTP/1.1" 500 14697
Internal Server Error: /support/4/
"GET /support/4/ HTTP/1.1" 500 14695
Internal Server Error: /support/trigger-test-error/
"GET /support/trigger-test-error/ HTTP/1.1" 500 14710
Internal Server Error: /support/trigger-test-error/
"GET /support/trigger-test-error/ HTTP/1.1" 500 14710
Internal Server Error: /support/trigger-test-error/
"GET /support/trigger-test-error/ HTTP/1.1" 500 14708
Internal Server Error: /support/trigger-test-error/
"GET /support/trigger-test-error/ HTTP/1.1" 500 14710
Internal Server Error: /support/trigger-test-error/
"GET /support/trigger-test-error/ HTTP/1.1" 500 14710
Internal Server Error: /support/trigger-test-error/
"GET /support/trigger-test-error/ HTTP/1.1" 500 14710
Internal Server Error: /support/trigger-test-error/
"GET /support/trigger-test-error/ HTTP/1.1" 500 14710
Internal Server Error: /support/trigger-automatic-error/
"GET /support/trigger-automatic-error/ HTTP/1.1" 500 14720
Internal Server Error: /api/programs/999/
"GET /api/programs/999/ HTTP/1.1" 500 14695
Internal Server Error: /api/programs/999/
"GET /api/programs/999/ HTTP/1.1" 500 14695
Internal Server Error: /api/programs/999/
"GET /api/programs/999/ HTTP/1.1" 500 14694
Internal Server Error: /api/programs/999/
"GET /api/programs/999/ HTTP/1.1" 500 14695
Internal Server Error: /api/programs/999/
"GET /api/programs/999/ HTTP/1.1" 500 14695
Internal Server Error: /api/programs/999/
"GET /api/programs/999/ HTTP/1.1" 500 14693
Internal Server Error: /api/programs/999/
"GET /api/programs/999/ HTTP/1.1" 500 14695
Internal Server Error: /item/1/edit/
"GET /item/1/edit/ HTTP/1.1" 500 14685
